Workbook

Sheet Financial Model
A1: Tháng | B1: Số nhân sự | C1: GTDN (Doanh thu) | D1: Lãi tháng | E1: Tổng lương chi | F1: Số dư vốn
A2: 0 | B2: =Assumptions!$B$5 -> 30 | C2: =Assumptions!$B$2 -> 2000000000 | D2: 0 | E2: 0 | F2: =C2 -> 2000000000
A3: 1 | B3: =B2+Assumptions!$B$6 -> 31 | C3: =C2*(1+Assumptions!$B$3) -> 2100000000 | D3: =Assumptions!$B$3*C2 -> 100000000 | E3: =B3*Assumptions!$B$4 -> 217000000 | F3: =F2+D3-E3 -> 1883000000
A4: 2 | B4: =B3+Assumptions!$B$6 -> 32 | C4: =C3*(1+Assumptions!$B$3) -> 2205000000 | D4: =Assumptions!$B$3*C3 -> 105000000 | E4: =B4*Assumptions!$B$4 -> 224000000 | F4: =F3+D4-E4 -> 1764000000
A5: 3 | B5: =B4+Assumptions!$B$6 -> 33 | C5: =C4*(1+Assumptions!$B$3) -> 2315250000 | D5: =Assumptions!$B$3*C4 -> 110250000 | E5: =B5*Assumptions!$B$4 -> 231000000 | F5: =F4+D5-E5 -> 1643250000
A6: 4 | B6: =B5+Assumptions!$B$6 -> 34 | C6: =C5*(1+Assumptions!$B$3) -> 2431012500 | D6: =Assumptions!$B$3*C5 -> 115762500 | E6: =B6*Assumptions!$B$4 -> 238000000 | F6: =F5+D6-E6 -> 1521012500
A7: 5 | B7: =B6+Assumptions!$B$6 -> 35 | C7: =C6*(1+Assumptions!$B$3) -> 2552563125 | D7: =Assumptions!$B$3*C6 -> 121550625 | E7: =B7*Assumptions!$B$4 -> 245000000 | F7: =F6+D7-E7 -> 1397563125
A8: 6 | B8: =B7+Assumptions!$B$6 -> 36 | C8: =C7*(1+Assumptions!$B$3) -> 2.6801913e+09 | D8: =Assumptions!$B$3*C7 -> 1.2762816e+08 | E8: =B8*Assumptions!$B$4 -> 252000000 | F8: =F7+D8-E8 -> 1.2731913e+09
A9: 7 | B9: =B8+Assumptions!$B$6 -> 37 | C9: =C8*(1+Assumptions!$B$3) -> 2.8142008e+09 | D9: =Assumptions!$B$3*C8 -> 1.3400956e+08 | E9: =B9*Assumptions!$B$4 -> 259000000 | F9: =F8+D9-E9 -> 1.1482008e+09
A10: 8 | B10: =B9+Assumptions!$B$6 -> 38 | C10: =C9*(1+Assumptions!$B$3) -> 2.9549109e+09 | D10: =Assumptions!$B$3*C9 -> 1.4071004e+08 | E10: =B10*Assumptions!$B$4 -> 266000000 | F10: =F9+D10-E10 -> 1.0229109e+09
A11: 9 | B11: =B10+Assumptions!$B$6 -> 39 | C11: =C10*(1+Assumptions!$B$3) -> 3.1026564e+09 | D11: =Assumptions!$B$3*C10 -> 1.4774554e+08 | E11: =B11*Assumptions!$B$4 -> 273000000 | F11: =F10+D11-E11 -> 8.9765643e+08
A12: 10 | B12: =B11+Assumptions!$B$6 -> 40 | C12: =C11*(1+Assumptions!$B$3) -> 3.2577893e+09 | D12: =Assumptions!$B$3*C11 -> 1.5513282e+08 | E12: =B12*Assumptions!$B$4 -> 280000000 | F12: =F11+D12-E12 -> 7.7278925e+08
A13: 11 | B13: =B12+Assumptions!$B$6 -> 41 | C13: =C12*(1+Assumptions!$B$3) -> 3.4206787e+09 | D13: =Assumptions!$B$3*C12 -> 1.6288946e+08 | E13: =B13*Assumptions!$B$4 -> 287000000 | F13: =F12+D13-E13 -> 6.4867872e+08
A14: 12 | B14: =B13+Assumptions!$B$6 -> 42 | C14: =C13*(1+Assumptions!$B$3) -> 3.5917127e+09 | D14: =Assumptions!$B$3*C13 -> 1.7103394e+08 | E14: =B14*Assumptions!$B$4 -> 294000000 | F14: =F13+D14-E14 -> 5.2571265e+08

Sheet Assumptions
A1: Tham số | B1: Giá trị
A2: Vốn đầu tư ban đầu (VND) | B2: 2000000000
A3: Tỷ lệ tăng trưởng hàng tháng | B3: 0.05
A4: Lương bình quân (VND/người) | B4: 7000000
A5: Số nhân sự ban đầu | B5: 30
A6: Tuyển mới hàng tháng | B6: 1

Sheet Dau_vao
A1: SECTION 1: THÔNG SỐ CỐ ĐỊNH
A2: Vốn đầu tư ban đầu | B2: =Assumptions!$B$2 -> 2000000000
A3: Tỷ lệ tăng trưởng | B3: =Assumptions!$B$3 -> 0.05
A4: Lương bình quân (Avg Salary) | B4: =Assumptions!$B$4 -> 7000000
A5: Tỷ lệ Lương cứng (Base %) | B5: 0.7
A6: Tỷ lệ Thưởng KPI (KPI %) | B6: 0.3
A8: SECTION 2-4: CƠ CẤU NHÂN SỰ
A9: Ban | B9: Role | C9: Số người | D9: Lương cơ bản | E9: Thưởng KPI | F9: Hệ số (Coef)
A10: Marketing | B10: Manager | C10: 1 | D10: =$B$4 * $F10 * $B$5 -> 12250000 | E10: =$B$4 * $F10 * $B$6 -> 5250000 | F10: 2.5
A11: Marketing | B11: Performance | C11: 2 | D11: =$B$4 * $F11 * $B$5 -> 7350000 | E11: =$B$4 * $F11 * $B$6 -> 3150000 | F11: 1.5
A12: Marketing | B12: Content | C12: 2 | D12: =$B$4 * $F12 * $B$5 -> 5880000 | E12: =$B$4 * $F12 * $B$6 -> 2520000 | F12: 1.2
A13: Marketing | B13: Creative | C13: 1 | D13: =$B$4 * $F13 * $B$5 -> 6370000 | E13: =$B$4 * $F13 * $B$6 -> 2730000 | F13: 1.3
A14: Sales | B14: Teamlead | C14: 1 | D14: =$B$4 * $F14 * $B$5 -> 9800000 | E14: =$B$4 * $F14 * $B$6 -> 4200000 | F14: 2
A15: Sales | B15: Defence | C15: 2 | D15: =$B$4 * $F15 * $B$5 -> 5880000 | E15: =$B$4 * $F15 * $B$6 -> 2520000 | F15: 1.2
A16: Sales | B16: Member | C16: 5 | D16: =$B$4 * $F16 * $B$5 -> 4900000 | E16: =$B$4 * $F16 * $B$6 -> 2100000 | F16: 1
A17: Accountant | B17: Accountant | C17: 1 | D17: =$B$4 * $F17 * $B$5 -> 7350000 | E17: =$B$4 * $F17 * $B$6 -> 3150000 | F17: 1.5
A18: Tech | B18: Automation | C18: 1 | D18: =$B$4 * $F18 * $B$5 -> 9800000 | E18: =$B$4 * $F18 * $B$6 -> 4200000 | F18: 2
A19: Tech | B19: Fullstack | C19: 2 | D19: =$B$4 * $F19 * $B$5 -> 10780000 | E19: =$B$4 * $F19 * $B$6 -> 4620000 | F19: 2.2
A20: Tech | B20: DevOps | C20: 1 | D20: =$B$4 * $F20 * $B$5 -> 12250000 | E20: =$B$4 * $F20 * $B$6 -> 5250000 | F20: 2.5
A21: OPS | B21: Quản lý vận hành | C21: 1 | D21: =$B$4 * $F21 * $B$5 -> 10780000 | E21: =$B$4 * $F21 * $B$6 -> 4620000 | F21: 2.2
... A24: OPS | B24: Hỗ trợ vận hành | C24: 2 | D24: =$B$4 * $F24 * $B$5 -> 4900000 | E24: =$B$4 * $F24 * $B$6 -> 2100000 | F24: 1

Sheet Luong_theo_ban
A1: Tháng | B1: Ban | C1: Role | D1: Số người | E1: Lương cứng | F1: Thưởng KPI | G1: Tổng role | H1: Tổng ban
A2: 1 | B2: Marketing | C2: Manager | D2: =Dau_vao!$C$10 -> 1 | E2: =Dau_vao!$D$10 -> 12250000 | F2: =Dau_vao!$E$10 -> 5250000 | G2: =D2*(E2+F2) -> 17500000 | H2: =SUMIFS(G:G, A:A, A2, B:B, B2) -> 64400000
A3: 1 | B3: Marketing | C3: Performance | D3: =Dau_vao!$C$11 -> 2 | E3: =Dau_vao!$D$11 -> 7350000 | F3: =Dau_vao!$E$11 -> 3150000 | G3: =D3*(E3+F3) -> 21000000 | H3: =SUMIFS(G:G, A:A, A3, B:B, B3) -> 64400000
A4: 1 | B4: Marketing | C4: Content | D4: =Dau_vao!$C$12 -> 2 | E4: =Dau_vao!$D$12 -> 5880000 | F4: =Dau_vao!$E$12 -> 2520000 | G4: =D4*(E4+F4) -> 16800000 | H4: =SUMIFS(G:G, A:A, A4, B:B, B4) -> 64400000
A5: 1 | B5: Marketing | C5: Creative | D5: =Dau_vao!$C$13 -> 1 | E5: =Dau_vao!$D$13 -> 6370000 | F5: =Dau_vao!$E$13 -> 2730000 | G5: =D5*(E5+F5) -> 9100000 | H5: =SUMIFS(G:G, A:A, A5, B:B, B5) -> 64400000
A6: 1 | B6: Sales | C6: Teamlead | D6: =Dau_vao!$C$14 -> 1 | E6: =Dau_vao!$D$14 -> 9800000 | F6: =Dau_vao!$E$14 -> 4200000 | G6: =D6*(E6+F6) -> 14000000 | H6: =SUMIFS(G:G, A:A, A6, B:B, B6) -> 72800000
A7: 1 | B7: Sales | C7: Defence | D7: =Dau_vao!$C$15 -> 2 | E7: =Dau_vao!$D$15 -> 5880000 | F7: =Dau_vao!$E$15 -> 2520000 | G7: =D7*(E7+F7) -> 16800000 | H7: =SUMIFS(G:G, A:A, A7, B:B, B7) -> 72800000
A8: 1 | B8: Sales | C8: Member | D8: =Dau_vao!$C$16 + (1 * Assumptions!$B$6) -> 6 | E8: =Dau_vao!$D$16 -> 4900000 | F8: =Dau_vao!$E$16 -> 2100000 | G8: =D8*(E8+F8) -> 42000000 | H8: =SUMIFS(G:G, A:A, A8, B:B, B8) -> 72800000
A9: 1 | B9: Accountant | C9: Accountant | D9: =Dau_vao!$C$17 -> 1 | E9: =Dau_vao!$D$17 -> 7350000 | F9: =Dau_vao!$E$17 -> 3150000 | G9: =D9*(E9+F9) -> 10500000 | H9: =SUMIFS(G:G, A:A, A9, B:B, B9) -> 10500000
A10: 1 | B10: Tech | C10: Automation | D10: =Dau_vao!$C$18 -> 1 | E10: =Dau_vao!$D$18 -> 9800000 | F10: =Dau_vao!$E$18 -> 4200000 | G10: =D10*(E10+F10) -> 14000000 | H10: =SUMIFS(G:G, A:A, A10, B:B, B10) -> 62300000
A11: 1 | B11: Tech | C11: Fullstack | D11: =Dau_vao!$C$19 -> 2 | E11: =Dau_vao!$D$19 -> 10780000 | F11: =Dau_vao!$E$19 -> 4620000 | G11: =D11*(E11+F11) -> 30800000 | H11: =SUMIFS(G:G, A:A, A11, B:B, B11) -> 62300000
A12: 1 | B12: Tech | C12: DevOps | D12: =Dau_vao!$C$20 -> 1 | E12: =Dau_vao!$D$20 -> 12250000 | F12: =Dau_vao!$E$20 -> 5250000 | G12: =D12*(E12+F12) -> 17500000 | H12: =SUMIFS(G:G, A:A, A12, B:B, B12) -> 62300000
A13: 1 | B13: OPS | C13: Quản lý vận hành | D13: =Dau_vao!$C$21 -> 1 | E13: =Dau_vao!$D$21 -> 10780000 | F13: =Dau_vao!$E$21 -> 4620000 | G13: =D13*(E13+F13) -> 15400000 | H13: =SUMIFS(G:G, A:A, A13, B:B, B13) -> 56700000
A14: 1 | B14: OPS | C14: Triển khai / Delivery | D14: =Dau_vao!$C$22 -> 2 | E14: =Dau_vao!$D$22 -> 5880000 | F14: =Dau_vao!$E$22 -> 2520000 | G14: =D14*(E14+F14) -> 16800000 | H14: =SUMIFS(G:G, A:A, A14, B:B, B14) -> 56700000
A15: 1 | B15: OPS | C15: Kiểm soát & tối ưu | D15: =Dau_vao!$C$23 -> 1 | E15: =Dau_vao!$D$23 -> 7350000 | F15: =Dau_vao!$E$23 -> 3150000 | G15: =D15*(E15+F15) -> 10500000 | H15: =SUMIFS(G:G, A:A, A15, B:B, B15) -> 56700000
A16: 1 | B16: OPS | C16: Hỗ trợ vận hành | D16: =Dau_vao!$C$24 -> 2 | E16: =Dau_vao!$D$24 -> 4900000 | F16: =Dau_vao!$E$24 -> 2100000 | G16: =D16*(E16+F16) -> 14000000 | H16: =SUMIFS(G:G, A:A, A16, B:B, B16) -> 56700000
A17: 2 | B17: Marketing | C17: Manager | D17: =Dau_vao!$C$10 -> 1 | E17: =Dau_vao!$D$10 -> 12250000 | F17: =Dau_vao!$E$10 -> 5250000 | G17: =D17*(E17+F17) -> 17500000 | H17: =SUMIFS(G:G, A:A, A17, B:B, B17) -> 64400000
A18: 2 | B18: Marketing | C18: Performance | D18: =Dau_vao!$C$11 -> 2 | E18: =Dau_vao!$D$11 -> 7350000 | F18: =Dau_vao!$E$11 -> 3150000 | G18: =D18*(E18+F18) -> 21000000 | H18: =SUMIFS(G:G, A:A, A18, B:B, B18) -> 64400000
A19: 2 | B19: Marketing | C19: Content | D19: =Dau_vao!$C$12 -> 2 | E19: =Dau_vao!$D$12 -> 5880000 | F19: =Dau_vao!$E$12 -> 2520000 | G19: =D19*(E19+F19) -> 16800000 | H19: =SUMIFS(G:G, A:A, A19, B:B, B19) -> 64400000
A20: 2 | B20: Marketing | C20: Creative | D20: =Dau_vao!$C$13 -> 1 | E20: =Dau_vao!$D$13 -> 6370000 | F20: =Dau_vao!$E$13 -> 2730000 | G20: =D20*(E20+F20) -> 9100000 | H20: =SUMIFS(G:G, A:A, A20, B:B, B20) -> 64400000
A21: 2 | B21: Sales | C21: Teamlead | D21: =Dau_vao!$C$14 -> 1 | E21: =Dau_vao!$D$14 -> 9800000 | F21: =Dau_vao!$E$14 -> 4200000 | G21: =D21*(E21+F21) -> 14000000 | H21: =SUMIFS(G:G, A:A, A21, B:B, B21) -> 79800000
A22: 2 | B22: Sales | C22: Defence | D22: =Dau_vao!$C$15 -> 2 | E22: =Dau_vao!$D$15 -> 5880000 | F22: =Dau_vao!$E$15 -> 2520000 | G22: =D22*(E22+F22) -> 16800000 | H22: =SUMIFS(G:G, A:A, A22, B:B, B22) -> 79800000
A23: 2 | B23: Sales | C23: Member | D23: =Dau_vao!$C$16 + (2 * Assumptions!$B$6) -> 7 | E23: =Dau_vao!$D$16 -> 4900000 | F23: =Dau_vao!$E$16 -> 2100000 | G23: =D23*(E23+F23) -> 49000000 | H23: =SUMIFS(G:G, A:A, A23, B:B, B23) -> 79800000
A24: 2 | B24: Accountant | C24: Accountant | D24: =Dau_vao!$C$17 -> 1 | E24: =Dau_vao!$D$17 -> 7350000 | F24: =Dau_vao!$E$17 -> 3150000 | G24: =D24*(E24+F24) -> 10500000 | H24: =SUMIFS(G:G, A:A, A24, B:B, B24) -> 10500000
A25: 2 | B25: Tech | C25: Automation | D25: =Dau_vao!$C$18 -> 1 | E25: =Dau_vao!$D$18 -> 9800000 | F25: =Dau_vao!$E$18 -> 4200000 | G25: =D25*(E25+F25) -> 14000000 | H25: =SUMIFS(G:G, A:A, A25, B:B, B25) -> 62300000
A26: 2 | B26: Tech | C26: Fullstack | D26: =Dau_vao!$C$19 -> 2 | E26: =Dau_vao!$D$19 -> 10780000 | F26: =Dau_vao!$E$19 -> 4620000 | G26: =D26*(E26+F26) -> 30800000 | H26: =SUMIFS(G:G, A:A, A26, B:B, B26) -> 62300000
A27: 2 | B27: Tech | C27: DevOps | D27: =Dau_vao!$C$20 -> 1 | E27: =Dau_vao!$D$20 -> 12250000 | F27: =Dau_vao!$E$20 -> 5250000 | G27: =D27*(E27+F27) -> 17500000 | H27: =SUMIFS(G:G, A:A, A27, B:B, B27) -> 62300000
A28: 2 | B28: OPS | C28: Quản lý vận hành | D28: =Dau_vao!$C$21 -> 1 | E28: =Dau_vao!$D$21 -> 10780000 | F28: =Dau_vao!$E$21 -> 4620000 | G28: =D28*(E28+F28) -> 15400000 | H28: =SUMIFS(G:G, A:A, A28, B:B, B28) -> 56700000
A29: 2 | B29: OPS | C29: Triển khai / Delivery | D29: =Dau_vao!$C$22 -> 2 | E29: =Dau_vao!$D$22 -> 5880000 | F29: =Dau_vao!$E$22 -> 2520000 | G29: =D29*(E29+F29) -> 16800000 | H29: =SUMIFS(G:G, A:A, A29, B:B, B29) -> 56700000
A30: 2 | B30: OPS | C30: Kiểm soát & tối ưu | D30: =Dau_vao!$C$23 -> 1 | E30: =Dau_vao!$D$23 -> 7350000 | F30: =Dau_vao!$E$23 -> 3150000 | G30: =D30*(E30+F30) -> 10500000 | H30: =SUMIFS(G:G, A:A, A30, B:B, B30) -> 56700000
A31: 2 | B31: OPS | C31: Hỗ trợ vận hành | D31: =Dau_vao!$C$24 -> 2 | E31: =Dau_vao!$D$24 -> 4900000 | F31: =Dau_vao!$E$24 -> 2100000 | G31: =D31*(E31+F31) -> 14000000 | H31: =SUMIFS(G:G, A:A, A31, B:B, B31) -> 56700000
A32: 3 | B32: Marketing | C32: Manager | D32: =Dau_vao!$C$10 -> 1 | E32: =Dau_vao!$D$10 -> 12250000 | F32: =Dau_vao!$E$10 -> 5250000 | G32: =D32*(E32+F32) -> 17500000 | H32: =SUMIFS(G:G, A:A, A32, B:B, B32) -> 64400000
A33: 3 | B33: Marketing | C33: Performance | D33: =Dau_vao!$C$11 -> 2 | E33: =Dau_vao!$D$11 -> 7350000 | F33: =Dau_vao!$E$11 -> 3150000 | G33: =D33*(E33+F33) -> 21000000 | H33: =SUMIFS(G:G, A:A, A33, B:B, B33) -> 64400000
A34: 3 | B34: Marketing | C34: Content | D34: =Dau_vao!$C$12 -> 2 | E34: =Dau_vao!$D$12 -> 5880000 | F34: =Dau_vao!$E$12 -> 2520000 | G34: =D34*(E34+F34) -> 16800000 | H34: =SUMIFS(G:G, A:A, A34, B:B, B34) -> 64400000
A35: 3 | B35: Marketing | C35: Creative | D35: =Dau_vao!$C$13 -> 1 | E35: =Dau_vao!$D$13 -> 6370000 | F35: =Dau_vao!$E$13 -> 2730000 | G35: =D35*(E35+F35) -> 9100000 | H35: =SUMIFS(G:G, A:A, A35, B:B, B35) -> 64400000
A36: 3 | B36: Sales | C36: Teamlead | D36: =Dau_vao!$C$14 -> 1 | E36: =Dau_vao!$D$14 -> 9800000 | F36: =Dau_vao!$E$14 -> 4200000 | G36: =D36*(E36+F36) -> 14000000 | H36: =SUMIFS(G:G, A:A, A36, B:B, B36) -> 86800000
A37: 3 | B37: Sales | C37: Defence | D37: =Dau_vao!$C$15 -> 2 | E37: =Dau_vao!$D$15 -> 5880000 | F37: =Dau_vao!$E$15 -> 2520000 | G37: =D37*(E37+F37) -> 16800000 | H37: =SUMIFS(G:G, A:A, A37, B:B, B37) -> 86800000
A38: 3 | B38: Sales | C38: Member | D38: =Dau_vao!$C$16 + (3 * Assumptions!$B$6) -> 8 | E38: =Dau_vao!$D$16 -> 4900000 | F38: =Dau_vao!$E$16 -> 2100000 | G38: =D38*(E38+F38) -> 56000000 | H38: =SUMIFS(G:G, A:A, A38, B:B, B38) -> 86800000
A39: 3 | B39: Accountant | C39: Accountant | D39: =Dau_vao!$C$17 -> 1 | E39: =Dau_vao!$D$17 -> 7350000 | F39: =Dau_vao!$E$17 -> 3150000 | G39: =D39*(E39+F39) -> 10500000 | H39: =SUMIFS(G:G, A:A, A39, B:B, B39) -> 10500000
A40: 3 | B40: Tech | C40: Automation | D40: =Dau_vao!$C$18 -> 1 | E40: =Dau_vao!$D$18 -> 9800000 | F40: =Dau_vao!$E$18 -> 4200000 | G40: =D40*(E40+F40) -> 14000000 | H40: =SUMIFS(G:G, A:A, A40, B:B, B40) -> 62300000
...

Sheet KPI_theo_ban
A1: Tháng | B1: Ban | C1: Tổng người | D1: Quỹ lương | E1: Công việc | F1: KPI | G1: Ghi chú
A2: 1 | B2: Marketing | C2: =SUMIFS(Luong_theo_ban!D:D, Luong_theo_ban!A:A, A2, Luong_theo_ban!B:B, B2) -> 6 | D2: =SUMIFS(Luong_theo_ban!G:G, Luong_theo_ban!A:A, A2, Luong_theo_ban!B:B, B2) -> 64400000
A3: 1 | B3: Sales | C3: =SUMIFS(Luong_theo_ban!D:D, Luong_theo_ban!A:A, A3, Luong_theo_ban!B:B, B3) -> 9 | D3: =SUMIFS(Luong_theo_ban!G:G, Luong_theo_ban!A:A, A3, Luong_theo_ban!B:B, B3) -> 72800000
A4: 1 | B4: Accountant | C4: =SUMIFS(Luong_theo_ban!D:D, Luong_theo_ban!A:A, A4, Luong_theo_ban!B:B, B4) -> 1 | D4: =SUMIFS(Luong_theo_ban!G:G, Luong_theo_ban!A:A, A4, Luong_theo_ban!B:B, B4) -> 10500000
A5: 1 | B5: Tech | C5: =SUMIFS(Luong_theo_ban!D:D, Luong_theo_ban!A:A, A5, Luong_theo_ban!B:B, B5) -> 4 | D5: =SUMIFS(Luong_theo_ban!G:G, Luong_theo_ban!A:A, A5, Luong_theo_ban!B:B, B5) -> 62300000
A6: 1 | B6: OPS | C6: =SUMIFS(Luong_theo_ban!D:D, Luong_theo_ban!A:A, A6, Luong_theo_ban!B:B, B6) -> 6 | D6: =SUMIFS(Luong_theo_ban!G:G, Luong_theo_ban!A:A, A6, Luong_theo_ban!B:B, B6) -> 56700000
A7: 2 | B7: Marketing | C7: =SUMIFS(Luong_theo_ban!D:D, Luong_theo_ban!A:A, A7, Luong_theo_ban!B:B, B7) -> 6 | D7: =SUMIFS(Luong_theo_ban!G:G, Luong_theo_ban!A:A, A7, Luong_theo_ban!B:B, B7) -> 64400000
A8: 2 | B8: Sales | C8: =SUMIFS(Luong_theo_ban!D:D, Luong_theo_ban!A:A, A8, Luong_theo_ban!B:B, B8) -> 10 | D8: =SUMIFS(Luong_theo_ban!G:G, Luong_theo_ban!A:A, A8, Luong_theo_ban!B:B, B8) -> 79800000
A9: 2 | B9: Accountant | C9: =SUMIFS(Luong_theo_ban!D:D, Luong_theo_ban!A:A, A9, Luong_theo_ban!B:B, B9) -> 1 | D9: =SUMIFS(Luong_theo_ban!G:G, Luong_theo_ban!A:A, A9, Luong_theo_ban!B:B, B9) -> 10500000
A10: 2 | B10: Tech | C10: =SUMIFS(Luong_theo_ban!D:D, Luong_theo_ban!A:A, A10, Luong_theo_ban!B:B, B10) -> 4 | D10: =SUMIFS(Luong_theo_ban!G:G, Luong_theo_ban!A:A, A10, Luong_theo_ban!B:B, B10) -> 62300000
A11: 2 | B11: OPS | C11: =SUMIFS(Luong_theo_ban!D:D, Luong_theo_ban!A:A, A11, Luong_theo_ban!B:B, B11) -> 6 | D11: =SUMIFS(Luong_theo_ban!G:G, Luong_theo_ban!A:A, A11, Luong_theo_ban!B:B, B11) -> 56700000
A12: 3 | B12: Marketing | C12: =SUMIFS(Luong_theo_ban!D:D, Luong_theo_ban!A:A, A12, Luong_theo_ban!B:B, B12) -> 6 | D12: =SUMIFS(Luong_theo_ban!G:G, Luong_theo_ban!A:A, A12, Luong_theo_ban!B:B, B12) -> 64400000
A13: 3 | B13: Sales | C13: =SUMIFS(Luong_theo_ban!D:D, Luong_theo_ban!A:A, A13, Luong_theo_ban!B:B, B13) -> 11 | D13: =SUMIFS(Luong_theo_ban!G:G, Luong_theo_ban!A:A, A13, Luong_theo_ban!B:B, B13) -> 86800000
... A61: 12 | B61: OPS | C61: =SUMIFS(Luong_theo_ban!D:D, Luong_theo_ban!A:A, A61, Luong_theo_ban!B:B, B61) -> 6 | D61: =SUMIFS(Luong_theo_ban!G:G, Luong_theo_ban!A:A, A61, Luong_theo_ban!B:B, B61) -> 56700000
